
2023-06-03 16:19:02,695	INFO worker.py:1553 -- Started a local Ray instance.
[36m(RolloutWorker pid=11672)[39m RESETTING ENVIRONMENT!!!!!!!!!!!!!
[36m(RolloutWorker pid=11672)[39m starting game.
[36m(RolloutWorker pid=11672)[39m RESETTING ENVIRONMENT!!!!!!!!!!!!!
[36m(RolloutWorker pid=11672)[39m 2023-06-03 16:19:15,657	WARNING env.py:156 -- Your env doesn't have a .spec.max_episode_steps attribute. Your horizon will default to infinity, and your environment will not be reset.
[36m(RolloutWorker pid=11672)[39m 2023-06-03 16:19:15,657	WARNING env.py:166 -- Your env reset() method appears to take 'seed' or 'return_info' arguments. Note that these are not yet supported in RLlib. Seeding will take place using 'env.seed()' and the info dict will not be returned from reset.
[36m(RolloutWorker pid=11672)[39m starting game.RESETTING ENVIRONMENT!!!!!!!!!!!!!
[36m(RolloutWorker pid=11672)
[36m(RolloutWorker pid=11672)[39m 2023-06-03 16:19:25.450 | INFO     | sc2.protocol:_execute:72 - Client status changed to Status.launched (was None)
[36m(RolloutWorker pid=11672)[39m 2023-06-03 16:19:25.450 | INFO     | sc2.controller:create_game:37 - Creating new game
[36m(RolloutWorker pid=11672)[39m 2023-06-03 16:19:25.450 | INFO     | sc2.controller:create_game:38 - Map:     TestMap3
[36m(RolloutWorker pid=11672)[39m 2023-06-03 16:19:25.450 | INFO     | sc2.controller:create_game:39 - Players: Bot ArmyBot(Terran), Computer Hard(Zerg, RandomBuild)
[36m(RolloutWorker pid=11672)[39m 2023-06-03 16:19:25.450 | INFO     | sc2.protocol:_execute:72 - Client status changed to Status.init_game (was Status.launched)
[36m(RolloutWorker pid=11672)[39m starting game.
[36m(RolloutWorker pid=11672)[39m 2023-06-03 16:19:36.692 | INFO     | sc2.protocol:_execute:72 - Client status changed to Status.launched (was None)
[36m(RolloutWorker pid=11672)[39m 2023-06-03 16:19:36.694 | INFO     | sc2.controller:create_game:37 - Creating new game
[36m(RolloutWorker pid=11672)[39m 2023-06-03 16:19:36.694 | INFO     | sc2.controller:create_game:38 - Map:     TestMap3
[36m(RolloutWorker pid=11672)[39m 2023-06-03 16:19:36.694 | INFO     | sc2.controller:create_game:39 - Players: Bot ArmyBot(Terran), Computer Hard(Zerg, RandomBuild)
[36m(RolloutWorker pid=11672)[39m 2023-06-03 16:19:36.698 | INFO     | sc2.protocol:_execute:72 - Client status changed to Status.init_game (was Status.launched)
[36m(RolloutWorker pid=11672)[39m 2023-06-03 16:19:40.019 | INFO     | sc2.protocol:_execute:72 - Client status changed to Status.in_game (was None)
[36m(RolloutWorker pid=11672)[39m 2023-06-03 16:19:40.021 | INFO     | sc2.main:_play_game:221 - Player 1 - Bot ArmyBot(Terran)
[36m(RolloutWorker pid=11672)[39m 2023-06-03 16:19:41.801 | INFO     | sc2.protocol:_execute:72 - Client status changed to Status.launched (was None)
[36m(RolloutWorker pid=11672)[39m 2023-06-03 16:19:41.801 | INFO     | sc2.controller:create_game:37 - Creating new game
[36m(RolloutWorker pid=11672)[39m 2023-06-03 16:19:41.801 | INFO     | sc2.controller:create_game:38 - Map:     TestMap3
[36m(RolloutWorker pid=11672)[39m 2023-06-03 16:19:41.801 | INFO     | sc2.controller:create_game:39 - Players: Bot ArmyBot(Terran), Computer Hard(Zerg, RandomBuild)
[36m(RolloutWorker pid=11672)[39m 2023-06-03 16:19:41.803 | INFO     | sc2.protocol:_execute:72 - Client status changed to Status.init_game (was Status.launched)
[36m(RolloutWorker pid=11672)[39m 2023-06-03 16:19:49.418 | INFO     | sc2.protocol:_execute:72 - Client status changed to Status.in_game (was None)
[36m(RolloutWorker pid=11672)[39m 2023-06-03 16:19:49.418 | INFO     | sc2.main:_play_game:221 - Player 1 - Bot ArmyBot(Terran)
[36m(RolloutWorker pid=11672)[39m 2023-06-03 16:19:53.236 | INFO     | sc2.protocol:_execute:72 - Client status changed to Status.in_game (was None)
[36m(RolloutWorker pid=11672)[39m 2023-06-03 16:19:53.236 | INFO     | sc2.main:_play_game:221 - Player 1 - Bot ArmyBot(Terran)
[36m(RolloutWorker pid=11672)[39m armybot at... 0
2023-06-03 16:19:55,603	ERROR actor_manager.py:496 -- Ray error, taking actor 1 out of service. The actor died because of an error raised in its creation task, [36mray::RolloutWorker.__init__()[39m (pid=11672, ip=127.0.0.1, repr=<ray.rllib.evaluation.rollout_worker.RolloutWorker object at 0x000001BB0EC418A0>)
  File "c:\Users\emil\Bachelor\RL-SC2-bot\QueueEnv.py", line 111, in step
    info = out["info"]
KeyError: 'info'
The above exception was the direct cause of the following exception:
[36mray::RolloutWorker.__init__()[39m (pid=11672, ip=127.0.0.1, repr=<ray.rllib.evaluation.rollout_worker.RolloutWorker object at 0x000001BB0EC418A0>)
  File "C:\Users\emil\AppData\Local\Programs\Python\Python310\lib\site-packages\ray\rllib\utils\pre_checks\env.py", line 82, in check_env
    check_gym_environments(env)
  File "C:\Users\emil\AppData\Local\Programs\Python\Python310\lib\site-packages\ray\rllib\utils\pre_checks\env.py", line 233, in check_gym_environments
    raise ValueError(
ValueError: Your gymnasium.Env's `step()` method raised an Exception!
During handling of the above exception, another exception occurred:
[36mray::RolloutWorker.__init__()[39m (pid=11672, ip=127.0.0.1, repr=<ray.rllib.evaluation.rollout_worker.RolloutWorker object at 0x000001BB0EC418A0>)
  File "python\ray\_raylet.pyx", line 850, in ray._raylet.execute_task
  File "python\ray\_raylet.pyx", line 902, in ray._raylet.execute_task
  File "python\ray\_raylet.pyx", line 857, in ray._raylet.execute_task
  File "python\ray\_raylet.pyx", line 861, in ray._raylet.execute_task
  File "python\ray\_raylet.pyx", line 803, in ray._raylet.execute_task.function_executor
  File "C:\Users\emil\AppData\Local\Programs\Python\Python310\lib\site-packages\ray\_private\function_manager.py", line 674, in actor_method_executor
    return method(__ray_actor, *args, **kwargs)
  File "C:\Users\emil\AppData\Local\Programs\Python\Python310\lib\site-packages\ray\util\tracing\tracing_helper.py", line 466, in _resume_span
    return method(self, *_args, **_kwargs)
  File "C:\Users\emil\AppData\Local\Programs\Python\Python310\lib\site-packages\ray\rllib\evaluation\rollout_worker.py", line 614, in __init__
    check_env(self.env)
  File "C:\Users\emil\AppData\Local\Programs\Python\Python310\lib\site-packages\ray\rllib\utils\pre_checks\env.py", line 93, in check_env
    raise ValueError(
ValueError: Traceback (most recent call last):
  File "C:\Users\emil\AppData\Local\Programs\Python\Python310\lib\site-packages\ray\rllib\utils\pre_checks\env.py", line 231, in check_gym_environments
    results = env.step(sampled_action)
  File "c:\Users\emil\Bachelor\RL-SC2-bot\QueueEnv.py", line 111, in step
    info = out["info"]
KeyError: 'info'
The above exception was the direct cause of the following exception:
[36mray::RolloutWorker.__init__()[39m (pid=11672, ip=127.0.0.1, repr=<ray.rllib.evaluation.rollout_worker.RolloutWorker object at 0x000001BB0EC418A0>)
  File "C:\Users\emil\AppData\Local\Programs\Python\Python310\lib\site-packages\ray\rllib\utils\pre_checks\env.py", line 82, in check_env
    check_gym_environments(env)
  File "C:\Users\emil\AppData\Local\Programs\Python\Python310\lib\site-packages\ray\rllib\utils\pre_checks\env.py", line 233, in check_gym_environments
    raise ValueError(
ValueError: Your gymnasium.Env's `step()` method raised an Exception!
The above error has been found in your environment! We've added a module for checking your custom environments. It may cause your experiment to fail if your environment is not set up correctly. You can disable this behavior via calling `config.environment(disable_env_checking=True)`. You can run the environment checking module standalone by calling ray.rllib.utils.check_env([your env]).
[36m(RolloutWorker pid=11672)[39m 2023-06-03 16:19:55,523	ERROR worker.py:772 -- Exception raised in creation task: The actor died because of an error raised in its creation task, [36mray::RolloutWorker.__init__()[39m (pid=11672, ip=127.0.0.1, repr=<ray.rllib.evaluation.rollout_worker.RolloutWorker object at 0x000001BB0EC418A0>)
[36m(RolloutWorker pid=11672)[39m   File "c:\Users\emil\Bachelor\RL-SC2-bot\QueueEnv.py", line 111, in step
[36m(RolloutWorker pid=11672)[39m     info = out["info"]
[36m(RolloutWorker pid=11672)[39m KeyError: 'info'
[36m(RolloutWorker pid=11672)
[36m(RolloutWorker pid=11672)[39m The above exception was the direct cause of the following exception:
[36m(RolloutWorker pid=11672)
[36m(RolloutWorker pid=11672)[39m [36mray::RolloutWorker.__init__()[39m (pid=11672, ip=127.0.0.1, repr=<ray.rllib.evaluation.rollout_worker.RolloutWorker object at 0x000001BB0EC418A0>)
[36m(RolloutWorker pid=11672)[39m   File "C:\Users\emil\AppData\Local\Programs\Python\Python310\lib\site-packages\ray\rllib\utils\pre_checks\env.py", line 82, in check_env
[36m(RolloutWorker pid=11672)[39m     check_gym_environments(env)
[36m(RolloutWorker pid=11672)[39m   File "C:\Users\emil\AppData\Local\Programs\Python\Python310\lib\site-packages\ray\rllib\utils\pre_checks\env.py", line 233, in check_gym_environments
[36m(RolloutWorker pid=11672)[39m     raise ValueError(
[36m(RolloutWorker pid=11672)[39m ValueError: Your gymnasium.Env's `step()` method raised an Exception!
[36m(RolloutWorker pid=11672)
[36m(RolloutWorker pid=11672)[39m During handling of the above exception, another exception occurred:
[36m(RolloutWorker pid=11672)
[36m(RolloutWorker pid=11672)[39m [36mray::RolloutWorker.__init__()[39m (pid=11672, ip=127.0.0.1, repr=<ray.rllib.evaluation.rollout_worker.RolloutWorker object at 0x000001BB0EC418A0>)
[36m(RolloutWorker pid=11672)[39m   File "python\ray\_raylet.pyx", line 850, in ray._raylet.execute_task
[36m(RolloutWorker pid=11672)[39m   File "python\ray\_raylet.pyx", line 902, in ray._raylet.execute_task
[36m(RolloutWorker pid=11672)[39m   File "python\ray\_raylet.pyx", line 857, in ray._raylet.execute_task
[36m(RolloutWorker pid=11672)[39m   File "python\ray\_raylet.pyx", line 861, in ray._raylet.execute_task
[36m(RolloutWorker pid=11672)[39m   File "python\ray\_raylet.pyx", line 803, in ray._raylet.execute_task.function_executor
[36m(RolloutWorker pid=11672)[39m   File "C:\Users\emil\AppData\Local\Programs\Python\Python310\lib\site-packages\ray\_private\function_manager.py", line 674, in actor_method_executor
[36m(RolloutWorker pid=11672)[39m     return method(__ray_actor, *args, **kwargs)
[36m(RolloutWorker pid=11672)[39m   File "C:\Users\emil\AppData\Local\Programs\Python\Python310\lib\site-packages\ray\util\tracing\tracing_helper.py", line 466, in _resume_span
[36m(RolloutWorker pid=11672)[39m     return method(self, *_args, **_kwargs)
[36m(RolloutWorker pid=11672)[39m   File "C:\Users\emil\AppData\Local\Programs\Python\Python310\lib\site-packages\ray\rllib\evaluation\rollout_worker.py", line 614, in __init__
[36m(RolloutWorker pid=11672)[39m     check_env(self.env)
[36m(RolloutWorker pid=11672)[39m   File "C:\Users\emil\AppData\Local\Programs\Python\Python310\lib\site-packages\ray\rllib\utils\pre_checks\env.py", line 93, in check_env
[36m(RolloutWorker pid=11672)[39m     raise ValueError(
[36m(RolloutWorker pid=11672)[39m ValueError: Traceback (most recent call last):
[36m(RolloutWorker pid=11672)[39m   File "C:\Users\emil\AppData\Local\Programs\Python\Python310\lib\site-packages\ray\rllib\utils\pre_checks\env.py", line 231, in check_gym_environments
[36m(RolloutWorker pid=11672)[39m     results = env.step(sampled_action)
[36m(RolloutWorker pid=11672)[39m   File "c:\Users\emil\Bachelor\RL-SC2-bot\QueueEnv.py", line 111, in step
[36m(RolloutWorker pid=11672)[39m     info = out["info"]
[36m(RolloutWorker pid=11672)[39m KeyError: 'info'
[36m(RolloutWorker pid=11672)
[36m(RolloutWorker pid=11672)[39m The above exception was the direct cause of the following exception:
[36m(RolloutWorker pid=11672)
[36m(RolloutWorker pid=11672)[39m [36mray::RolloutWorker.__init__()[39m (pid=11672, ip=127.0.0.1, repr=<ray.rllib.evaluation.rollout_worker.RolloutWorker object at 0x000001BB0EC418A0>)
[36m(RolloutWorker pid=11672)[39m   File "C:\Users\emil\AppData\Local\Programs\Python\Python310\lib\site-packages\ray\rllib\utils\pre_checks\env.py", line 82, in check_env
[36m(RolloutWorker pid=11672)[39m     check_gym_environments(env)
[36m(RolloutWorker pid=11672)[39m   File "C:\Users\emil\AppData\Local\Programs\Python\Python310\lib\site-packages\ray\rllib\utils\pre_checks\env.py", line 233, in check_gym_environmentsTraceback (most recent call last):
[36m(RolloutWorker pid=11672)[39m     raise ValueError(  File "C:\Users\emil\AppData\Local\Programs\Python\Python310\lib\site-packages\ray\rllib\evaluation\worker_set.py", line 170, in __init__
    self._setup(
[36m(RolloutWorker pid=11672)[39m ValueError: Your gymnasium.Env's `step()` method raised an Exception!  File "C:\Users\emil\AppData\Local\Programs\Python\Python310\lib\site-packages\ray\rllib\evaluation\worker_set.py", line 240, in _setup
    self.add_workers(
[36m(RolloutWorker pid=11672)[39m   File "C:\Users\emil\AppData\Local\Programs\Python\Python310\lib\site-packages\ray\rllib\evaluation\worker_set.py", line 614, in add_workers
    raise result.get()
[36m(RolloutWorker pid=11672)[39m The above error has been found in your environment! We've added a module for checking your custom environments. It may cause your experiment to fail if your environment is not set up correctly. You can disable this behavior via calling `config.environment(disable_env_checking=True)`. You can run the environment checking module standalone by calling ray.rllib.utils.check_env([your env]).  File "C:\Users\emil\AppData\Local\Programs\Python\Python310\lib\site-packages\ray\rllib\utils\actor_manager.py", line 477, in __fetch_result
    result = ray.get(r)
  File "C:\Users\emil\AppData\Local\Programs\Python\Python310\lib\site-packages\ray\_private\client_mode_hook.py", line 105, in wrapper
    return func(*args, **kwargs)
  File "C:\Users\emil\AppData\Local\Programs\Python\Python310\lib\site-packages\ray\_private\worker.py", line 2382, in get
    raise value
ray.exceptions.RayActorError: The actor died because of an error raised in its creation task, [36mray::RolloutWorker.__init__()[39m (pid=11672, ip=127.0.0.1, repr=<ray.rllib.evaluation.rollout_worker.RolloutWorker object at 0x000001BB0EC418A0>)
  File "c:\Users\emil\Bachelor\RL-SC2-bot\QueueEnv.py", line 111, in step
    info = out["info"]
KeyError: 'info'
The above exception was the direct cause of the following exception:
[36mray::RolloutWorker.__init__()[39m (pid=11672, ip=127.0.0.1, repr=<ray.rllib.evaluation.rollout_worker.RolloutWorker object at 0x000001BB0EC418A0>)
  File "C:\Users\emil\AppData\Local\Programs\Python\Python310\lib\site-packages\ray\rllib\utils\pre_checks\env.py", line 82, in check_env
    check_gym_environments(env)
  File "C:\Users\emil\AppData\Local\Programs\Python\Python310\lib\site-packages\ray\rllib\utils\pre_checks\env.py", line 233, in check_gym_environments
    raise ValueError(
ValueError: Your gymnasium.Env's `step()` method raised an Exception!
During handling of the above exception, another exception occurred:
[36mray::RolloutWorker.__init__()[39m (pid=11672, ip=127.0.0.1, repr=<ray.rllib.evaluation.rollout_worker.RolloutWorker object at 0x000001BB0EC418A0>)
  File "python\ray\_raylet.pyx", line 850, in ray._raylet.execute_task
  File "python\ray\_raylet.pyx", line 902, in ray._raylet.execute_task
  File "python\ray\_raylet.pyx", line 857, in ray._raylet.execute_task
  File "python\ray\_raylet.pyx", line 861, in ray._raylet.execute_task
  File "python\ray\_raylet.pyx", line 803, in ray._raylet.execute_task.function_executor
  File "C:\Users\emil\AppData\Local\Programs\Python\Python310\lib\site-packages\ray\_private\function_manager.py", line 674, in actor_method_executor
    return method(__ray_actor, *args, **kwargs)
  File "C:\Users\emil\AppData\Local\Programs\Python\Python310\lib\site-packages\ray\util\tracing\tracing_helper.py", line 466, in _resume_span
    return method(self, *_args, **_kwargs)
  File "C:\Users\emil\AppData\Local\Programs\Python\Python310\lib\site-packages\ray\rllib\evaluation\rollout_worker.py", line 614, in __init__
    check_env(self.env)
  File "C:\Users\emil\AppData\Local\Programs\Python\Python310\lib\site-packages\ray\rllib\utils\pre_checks\env.py", line 93, in check_env
    raise ValueError(
ValueError: Traceback (most recent call last):
  File "C:\Users\emil\AppData\Local\Programs\Python\Python310\lib\site-packages\ray\rllib\utils\pre_checks\env.py", line 231, in check_gym_environments
    results = env.step(sampled_action)
  File "c:\Users\emil\Bachelor\RL-SC2-bot\QueueEnv.py", line 111, in step
    info = out["info"]
KeyError: 'info'
The above exception was the direct cause of the following exception:
[36mray::RolloutWorker.__init__()[39m (pid=11672, ip=127.0.0.1, repr=<ray.rllib.evaluation.rollout_worker.RolloutWorker object at 0x000001BB0EC418A0>)
  File "C:\Users\emil\AppData\Local\Programs\Python\Python310\lib\site-packages\ray\rllib\utils\pre_checks\env.py", line 82, in check_env
    check_gym_environments(env)
  File "C:\Users\emil\AppData\Local\Programs\Python\Python310\lib\site-packages\ray\rllib\utils\pre_checks\env.py", line 233, in check_gym_environments
    raise ValueError(
ValueError: Your gymnasium.Env's `step()` method raised an Exception!
The above error has been found in your environment! We've added a module for checking your custom environments. It may cause your experiment to fail if your environment is not set up correctly. You can disable this behavior via calling `config.environment(disable_env_checking=True)`. You can run the environment checking module standalone by calling ray.rllib.utils.check_env([your env]).
During handling of the above exception, another exception occurred:
Traceback (most recent call last):
  File "c:\Users\emil\Bachelor\RL-SC2-bot\QueueEnv.py", line 190, in <module>
    train_ppo()
  File "c:\Users\emil\Bachelor\RL-SC2-bot\QueueEnv.py", line 155, in train_ppo
    .build()
  File "C:\Users\emil\AppData\Local\Programs\Python\Python310\lib\site-packages\ray\rllib\algorithms\algorithm_config.py", line 926, in build
    return algo_class(
  File "C:\Users\emil\AppData\Local\Programs\Python\Python310\lib\site-packages\ray\rllib\algorithms\algorithm.py", line 445, in __init__
    super().__init__(
  File "C:\Users\emil\AppData\Local\Programs\Python\Python310\lib\site-packages\ray\tune\trainable\trainable.py", line 169, in __init__
    self.setup(copy.deepcopy(self.config))
  File "C:\Users\emil\AppData\Local\Programs\Python\Python310\lib\site-packages\ray\rllib\algorithms\algorithm.py", line 571, in setup
    self.workers = WorkerSet(
  File "C:\Users\emil\AppData\Local\Programs\Python\Python310\lib\site-packages\ray\rllib\evaluation\worker_set.py", line 192, in __init__
    raise e.args[0].args[2]
ValueError: Traceback (most recent call last):
  File "C:\Users\emil\AppData\Local\Programs\Python\Python310\lib\site-packages\ray\rllib\utils\pre_checks\env.py", line 231, in check_gym_environments
    results = env.step(sampled_action)
  File "c:\Users\emil\Bachelor\RL-SC2-bot\QueueEnv.py", line 111, in step
    info = out["info"]
KeyError: 'info'
The above exception was the direct cause of the following exception:
Traceback (most recent call last):
  File "C:\Users\emil\AppData\Local\Programs\Python\Python310\lib\site-packages\ray\rllib\utils\pre_checks\env.py", line 82, in check_env
    check_gym_environments(env)
  File "C:\Users\emil\AppData\Local\Programs\Python\Python310\lib\site-packages\ray\rllib\utils\pre_checks\env.py", line 233, in check_gym_environments
    raise ValueError(
ValueError: Your gymnasium.Env's `step()` method raised an Exception!
The above error has been found in your environment! We've added a module for checking your custom environments. It may cause your experiment to fail if your environment is not set up correctly. You can disable this behavior via calling `config.environment(disable_env_checking=True)`. You can run the environment checking module standalone by calling ray.rllib.utils.check_env([your env]).
Traceback (most recent call last):
  File "C:\Users\emil\AppData\Local\Programs\Python\Python310\lib\site-packages\ray\rllib\evaluation\worker_set.py", line 170, in __init__
    self._setup(
  File "C:\Users\emil\AppData\Local\Programs\Python\Python310\lib\site-packages\ray\rllib\evaluation\worker_set.py", line 240, in _setup
    self.add_workers(
  File "C:\Users\emil\AppData\Local\Programs\Python\Python310\lib\site-packages\ray\rllib\evaluation\worker_set.py", line 614, in add_workers
    raise result.get()
  File "C:\Users\emil\AppData\Local\Programs\Python\Python310\lib\site-packages\ray\rllib\utils\actor_manager.py", line 477, in __fetch_result
    result = ray.get(r)
  File "C:\Users\emil\AppData\Local\Programs\Python\Python310\lib\site-packages\ray\_private\client_mode_hook.py", line 105, in wrapper
    return func(*args, **kwargs)
  File "C:\Users\emil\AppData\Local\Programs\Python\Python310\lib\site-packages\ray\_private\worker.py", line 2382, in get
    raise value
ray.exceptions.RayActorError: The actor died because of an error raised in its creation task, [36mray::RolloutWorker.__init__()[39m (pid=11672, ip=127.0.0.1, repr=<ray.rllib.evaluation.rollout_worker.RolloutWorker object at 0x000001BB0EC418A0>)
  File "c:\Users\emil\Bachelor\RL-SC2-bot\QueueEnv.py", line 111, in step
    info = out["info"]
KeyError: 'info'
The above exception was the direct cause of the following exception:
[36mray::RolloutWorker.__init__()[39m (pid=11672, ip=127.0.0.1, repr=<ray.rllib.evaluation.rollout_worker.RolloutWorker object at 0x000001BB0EC418A0>)
  File "C:\Users\emil\AppData\Local\Programs\Python\Python310\lib\site-packages\ray\rllib\utils\pre_checks\env.py", line 82, in check_env
    check_gym_environments(env)
  File "C:\Users\emil\AppData\Local\Programs\Python\Python310\lib\site-packages\ray\rllib\utils\pre_checks\env.py", line 233, in check_gym_environments
    raise ValueError(
ValueError: Your gymnasium.Env's `step()` method raised an Exception!
During handling of the above exception, another exception occurred:
[36mray::RolloutWorker.__init__()[39m (pid=11672, ip=127.0.0.1, repr=<ray.rllib.evaluation.rollout_worker.RolloutWorker object at 0x000001BB0EC418A0>)
  File "python\ray\_raylet.pyx", line 850, in ray._raylet.execute_task
  File "python\ray\_raylet.pyx", line 902, in ray._raylet.execute_task
  File "python\ray\_raylet.pyx", line 857, in ray._raylet.execute_task
  File "python\ray\_raylet.pyx", line 861, in ray._raylet.execute_task
  File "python\ray\_raylet.pyx", line 803, in ray._raylet.execute_task.function_executor
  File "C:\Users\emil\AppData\Local\Programs\Python\Python310\lib\site-packages\ray\_private\function_manager.py", line 674, in actor_method_executor
    return method(__ray_actor, *args, **kwargs)
  File "C:\Users\emil\AppData\Local\Programs\Python\Python310\lib\site-packages\ray\util\tracing\tracing_helper.py", line 466, in _resume_span
    return method(self, *_args, **_kwargs)
  File "C:\Users\emil\AppData\Local\Programs\Python\Python310\lib\site-packages\ray\rllib\evaluation\rollout_worker.py", line 614, in __init__
    check_env(self.env)
  File "C:\Users\emil\AppData\Local\Programs\Python\Python310\lib\site-packages\ray\rllib\utils\pre_checks\env.py", line 93, in check_env
    raise ValueError(
ValueError: Traceback (most recent call last):
  File "C:\Users\emil\AppData\Local\Programs\Python\Python310\lib\site-packages\ray\rllib\utils\pre_checks\env.py", line 231, in check_gym_environments
    results = env.step(sampled_action)
  File "c:\Users\emil\Bachelor\RL-SC2-bot\QueueEnv.py", line 111, in step
    info = out["info"]
KeyError: 'info'
The above exception was the direct cause of the following exception:
[36mray::RolloutWorker.__init__()[39m (pid=11672, ip=127.0.0.1, repr=<ray.rllib.evaluation.rollout_worker.RolloutWorker object at 0x000001BB0EC418A0>)
  File "C:\Users\emil\AppData\Local\Programs\Python\Python310\lib\site-packages\ray\rllib\utils\pre_checks\env.py", line 82, in check_env
    check_gym_environments(env)
  File "C:\Users\emil\AppData\Local\Programs\Python\Python310\lib\site-packages\ray\rllib\utils\pre_checks\env.py", line 233, in check_gym_environments
    raise ValueError(
ValueError: Your gymnasium.Env's `step()` method raised an Exception!
The above error has been found in your environment! We've added a module for checking your custom environments. It may cause your experiment to fail if your environment is not set up correctly. You can disable this behavior via calling `config.environment(disable_env_checking=True)`. You can run the environment checking module standalone by calling ray.rllib.utils.check_env([your env]).
During handling of the above exception, another exception occurred:
Traceback (most recent call last):
  File "c:\Users\emil\Bachelor\RL-SC2-bot\QueueEnv.py", line 190, in <module>
    train_ppo()
  File "c:\Users\emil\Bachelor\RL-SC2-bot\QueueEnv.py", line 155, in train_ppo
    .build()
  File "C:\Users\emil\AppData\Local\Programs\Python\Python310\lib\site-packages\ray\rllib\algorithms\algorithm_config.py", line 926, in build
    return algo_class(
  File "C:\Users\emil\AppData\Local\Programs\Python\Python310\lib\site-packages\ray\rllib\algorithms\algorithm.py", line 445, in __init__
    super().__init__(
  File "C:\Users\emil\AppData\Local\Programs\Python\Python310\lib\site-packages\ray\tune\trainable\trainable.py", line 169, in __init__
    self.setup(copy.deepcopy(self.config))
  File "C:\Users\emil\AppData\Local\Programs\Python\Python310\lib\site-packages\ray\rllib\algorithms\algorithm.py", line 571, in setup
    self.workers = WorkerSet(
  File "C:\Users\emil\AppData\Local\Programs\Python\Python310\lib\site-packages\ray\rllib\evaluation\worker_set.py", line 192, in __init__
    raise e.args[0].args[2]
ValueError: Traceback (most recent call last):
  File "C:\Users\emil\AppData\Local\Programs\Python\Python310\lib\site-packages\ray\rllib\utils\pre_checks\env.py", line 231, in check_gym_environments
    results = env.step(sampled_action)
  File "c:\Users\emil\Bachelor\RL-SC2-bot\QueueEnv.py", line 111, in step
    info = out["info"]
KeyError: 'info'
The above exception was the direct cause of the following exception:
Traceback (most recent call last):
  File "C:\Users\emil\AppData\Local\Programs\Python\Python310\lib\site-packages\ray\rllib\utils\pre_checks\env.py", line 82, in check_env
    check_gym_environments(env)
  File "C:\Users\emil\AppData\Local\Programs\Python\Python310\lib\site-packages\ray\rllib\utils\pre_checks\env.py", line 233, in check_gym_environments
    raise ValueError(
ValueError: Your gymnasium.Env's `step()` method raised an Exception!
The above error has been found in your environment! We've added a module for checking your custom environments. It may cause your experiment to fail if your environment is not set up correctly. You can disable this behavior via calling `config.environment(disable_env_checking=True)`. You can run the environment checking module standalone by calling ray.rllib.utils.check_env([your env]).