
2023-06-08 12:30:40,227	INFO worker.py:1625 -- Started a local Ray instance.
[36m(RolloutWorker pid=84064)[39m !RESETTING ENVIRONMENT!
[36m(RolloutWorker pid=84064)[39m starting game.
[36m(RolloutWorker pid=84064)[39m !RESETTING ENVIRONMENT!
[36m(RolloutWorker pid=84064)[39m 2023-06-08 12:30:52,185	WARNING env.py:155 -- Your env doesn't have a .spec.max_episode_steps attribute. Your horizon will default to infinity, and your environment will not be reset.
[36m(RolloutWorker pid=84064)[39m starting game.
[36m(RolloutWorker pid=84064)[39m !RESETTING ENVIRONMENT!
[36m(RolloutWorker pid=84064)[39m starting game.
[36m(RolloutWorker pid=84064)[39m 2023-06-08 12:31:04.286 | INFO     | sc2.protocol:_execute:72 - Client status changed to Status.launched (was None)
[36m(RolloutWorker pid=84064)[39m 2023-06-08 12:31:04.286 | INFO     | sc2.controller:create_game:37 - Creating new game
[36m(RolloutWorker pid=84064)[39m 2023-06-08 12:31:04.286 | INFO     | sc2.controller:create_game:38 - Map:     TrainingMapResource
[36m(RolloutWorker pid=84064)[39m 2023-06-08 12:31:04.286 | INFO     | sc2.controller:create_game:39 - Players: Bot ArmyBot(Terran), Computer Hard(Zerg, RandomBuild)
[36m(RolloutWorker pid=84064)[39m 2023-06-08 12:31:04.286 | INFO     | sc2.protocol:_execute:72 - Client status changed to Status.init_game (was Status.launched)
[36m(RolloutWorker pid=84064)[39m 2023-06-08 12:31:08.909 | INFO     | sc2.protocol:_execute:72 - Client status changed to Status.in_game (was None)
[36m(RolloutWorker pid=84064)[39m 2023-06-08 12:31:08.909 | INFO     | sc2.main:_play_game:221 - Player 1 - Bot ArmyBot(Terran)
[36m(RolloutWorker pid=84064)[39m 2023-06-08 12:31:11.696 | INFO     | sc2.protocol:_execute:72 - Client status changed to Status.launched (was None)
[36m(RolloutWorker pid=84064)[39m 2023-06-08 12:31:11.696 | INFO     | sc2.controller:create_game:37 - Creating new game
[36m(RolloutWorker pid=84064)[39m 2023-06-08 12:31:11.696 | INFO     | sc2.controller:create_game:38 - Map:     TrainingMapResource
[36m(RolloutWorker pid=84064)[39m 2023-06-08 12:31:11.696 | INFO     | sc2.controller:create_game:39 - Players: Bot ArmyBot(Terran), Computer Hard(Zerg, RandomBuild)
[36m(RolloutWorker pid=84064)[39m 2023-06-08 12:31:11.696 | INFO     | sc2.protocol:_execute:72 - Client status changed to Status.init_game (was Status.launched)
[36m(RolloutWorker pid=84064)[39m 2023-06-08 12:31:18.421 | ERROR    | sc2.protocol:__request:50 - Cannot receive: Connection already closed.
[36m(RolloutWorker pid=84064)[39m 2023-06-08 12:31:18.421 | INFO     | sc2.sc2process:_close_connection:231 - Closing connection at 60981...
[36m(RolloutWorker pid=84064)[39m 2023-06-08 12:31:18.421 | INFO     | sc2.sc2process:kill_all:33 - kill_switch: Process cleanup for 3 processes
[36m(RolloutWorker pid=84064)[39m 2023-06-08 12:31:18.862 | ERROR    | sc2.protocol:__request:50 - Cannot receive: Connection already closed.
[36m(RolloutWorker pid=84064)[39m 2023-06-08 12:31:18.862 | INFO     | sc2.sc2process:_close_connection:231 - Closing connection at 60937...
[36m(RolloutWorker pid=84064)[39m 2023-06-08 12:31:18.863 | INFO     | sc2.sc2process:kill_all:33 - kill_switch: Process cleanup for 3 processes
[36m(RolloutWorker pid=84064)[39m 2023-06-08 12:31:18.863 | ERROR    | sc2.sc2process:_clean:257 - KILLED
[36m(RolloutWorker pid=84064)[39m 2023-06-08 12:31:18.930 | ERROR    | sc2.sc2process:_clean:257 - KILLED
[36m(RolloutWorker pid=84064)[39m 2023-06-08 12:31:18.931 | ERROR    | sc2.sc2process:_clean:257 - KILLED
[36m(RolloutWorker pid=84064)[39m Exception in thread Thread-8:
[36m(RolloutWorker pid=84064)[39m Traceback (most recent call last):
[36m(RolloutWorker pid=84064)[39m   File "C:\Users\Emil WC\AppData\Local\Programs\Python\Python310\lib\site-packages\sc2\protocol.py", line 45, in __request
[36m(RolloutWorker pid=84064)[39m     response_bytes = await self._ws.receive_bytes()
[36m(RolloutWorker pid=84064)[39m   File "C:\Users\Emil WC\AppData\Local\Programs\Python\Python310\lib\site-packages\aiohttp\client_ws.py", line 281, in receive_bytes
[36m(RolloutWorker pid=84064)[39m     raise TypeError(f"Received message {msg.type}:{msg.data!r} is not bytes")
[36m(RolloutWorker pid=84064)[39m TypeError: Received message 257:None is not bytes
[36m(RolloutWorker pid=84064)
[36m(RolloutWorker pid=84064)[39m The above exception was the direct cause of the following exception:
[36m(RolloutWorker pid=84064)
[36m(RolloutWorker pid=84064)[39m Traceback (most recent call last):
[36m(RolloutWorker pid=84064)[39m   File "C:\Users\Emil WC\AppData\Local\Programs\Python\Python310\lib\threading.py", line 1016, in _bootstrap_inner
[36m(RolloutWorker pid=84064)[39m     self.run()
[36m(RolloutWorker pid=84064)[39m   File "c:\Users\Emil WC\Bachelor\RL-SC2-bot\QueueEnv.py", line 44, in run
[36m(RolloutWorker pid=84064)[39m     result = run_game(  # run_game is a function that runs the game.
[36m(RolloutWorker pid=84064)[39m   File "C:\Users\Emil WC\AppData\Local\Programs\Python\Python310\lib\site-packages\sc2\main.py", line 496, in run_game
[36m(RolloutWorker pid=84064)[39m     result: Result = asyncio.run(_host_game(map_settings, players, **kwargs))
[36m(RolloutWorker pid=84064)[39m   File "C:\Users\Emil WC\AppData\Local\Programs\Python\Python310\lib\asyncio\runners.py", line 44, in run
[36m(RolloutWorker pid=84064)[39m     return loop.run_until_complete(main)
[36m(RolloutWorker pid=84064)[39m   File "C:\Users\Emil WC\AppData\Local\Programs\Python\Python310\lib\asyncio\base_events.py", line 649, in run_until_complete
[36m(RolloutWorker pid=84064)[39m     return future.result()
[36m(RolloutWorker pid=84064)[39m   File "C:\Users\Emil WC\AppData\Local\Programs\Python\Python310\lib\site-packages\sc2\main.py", line 360, in _host_game
[36m(RolloutWorker pid=84064)[39m     await server.ping()
[36m(RolloutWorker pid=84064)[39m   File "C:\Users\Emil WC\AppData\Local\Programs\Python\Python310\lib\site-packages\sc2\protocol.py", line 82, in ping
[36m(RolloutWorker pid=84064)[39m     result = await self._execute(ping=sc_pb.RequestPing())
[36m(RolloutWorker pid=84064)[39m   File "C:\Users\Emil WC\AppData\Local\Programs\Python\Python310\lib\site-packages\sc2\protocol.py", line 68, in _execute
[36m(RolloutWorker pid=84064)[39m     response = await self.__request(sc_pb.Request(**kwargs))
[36m(RolloutWorker pid=84064)[39m   File "C:\Users\Emil WC\AppData\Local\Programs\Python\Python310\lib\site-packages\sc2\protocol.py", line 51, in __request
[36m(RolloutWorker pid=84064)[39m     raise ConnectionAlreadyClosed("Connection already closed.") from exc
[36m(RolloutWorker pid=84064)[39m sc2.protocol.ConnectionAlreadyClosed: Connection already closed.
[36m(RolloutWorker pid=84064)[39m Exception in thread Thread-7:
[36m(RolloutWorker pid=84064)[39m Traceback (most recent call last):
[36m(RolloutWorker pid=84064)[39m   File "C:\Users\Emil WC\AppData\Local\Programs\Python\Python310\lib\site-packages\sc2\protocol.py", line 45, in __request
[36m(RolloutWorker pid=84064)[39m     response_bytes = await self._ws.receive_bytes()
[36m(RolloutWorker pid=84064)[39m   File "C:\Users\Emil WC\AppData\Local\Programs\Python\Python310\lib\site-packages\aiohttp\client_ws.py", line 281, in receive_bytes
[36m(RolloutWorker pid=84064)[39m     raise TypeError(f"Received message {msg.type}:{msg.data!r} is not bytes")
[36m(RolloutWorker pid=84064)[39m TypeError: Received message 257:None is not bytes
[36m(RolloutWorker pid=84064)
[36m(RolloutWorker pid=84064)[39m The above exception was the direct cause of the following exception:
[36m(RolloutWorker pid=84064)
[36m(RolloutWorker pid=84064)[39m Traceback (most recent call last):
[36m(RolloutWorker pid=84064)[39m   File "C:\Users\Emil WC\AppData\Local\Programs\Python\Python310\lib\threading.py", line 1016, in _bootstrap_inner
[36m(RolloutWorker pid=84064)[39m     self.run()
[36m(RolloutWorker pid=84064)[39m   File "c:\Users\Emil WC\Bachelor\RL-SC2-bot\QueueEnv.py", line 44, in run
[36m(RolloutWorker pid=84064)[39m     result = run_game(  # run_game is a function that runs the game.
[36m(RolloutWorker pid=84064)[39m   File "C:\Users\Emil WC\AppData\Local\Programs\Python\Python310\lib\site-packages\sc2\main.py", line 496, in run_game
[36m(RolloutWorker pid=84064)[39m     result: Result = asyncio.run(_host_game(map_settings, players, **kwargs))
[36m(RolloutWorker pid=84064)[39m   File "C:\Users\Emil WC\AppData\Local\Programs\Python\Python310\lib\asyncio\runners.py", line 44, in run
[36m(RolloutWorker pid=84064)[39m     return loop.run_until_complete(main)
[36m(RolloutWorker pid=84064)[39m   File "C:\Users\Emil WC\AppData\Local\Programs\Python\Python310\lib\asyncio\base_events.py", line 649, in run_until_complete
[36m(RolloutWorker pid=84064)[39m     return future.result()
[36m(RolloutWorker pid=84064)[39m   File "C:\Users\Emil WC\AppData\Local\Programs\Python\Python310\lib\site-packages\sc2\main.py", line 369, in _host_game
[36m(RolloutWorker pid=84064)[39m     result = await _play_game(players[0], client, realtime, portconfig, game_time_limit, rgb_render_config)
[36m(RolloutWorker pid=84064)[39m   File "C:\Users\Emil WC\AppData\Local\Programs\Python\Python310\lib\site-packages\sc2\main.py", line 218, in _play_game
[36m(RolloutWorker pid=84064)[39m     player_id = await client.join_game(
[36m(RolloutWorker pid=84064)[39m   File "C:\Users\Emil WC\AppData\Local\Programs\Python\Python310\lib\site-packages\sc2\client.py", line 99, in join_game
[36m(RolloutWorker pid=84064)[39m     result = await self._execute(join_game=req)
[36m(RolloutWorker pid=84064)[39m   File "C:\Users\Emil WC\AppData\Local\Programs\Python\Python310\lib\site-packages\sc2\protocol.py", line 68, in _execute
[36m(RolloutWorker pid=84064)[39m     response = await self.__request(sc_pb.Request(**kwargs))
[36m(RolloutWorker pid=84064)[39m   File "C:\Users\Emil WC\AppData\Local\Programs\Python\Python310\lib\site-packages\sc2\protocol.py", line 51, in __request
[36m(RolloutWorker pid=84064)[39m     raise ConnectionAlreadyClosed("Connection already closed.") from exc
[36m(RolloutWorker pid=84064)[39m sc2.protocol.ConnectionAlreadyClosed: Connection already closed.
